Workbook

Sheet Candidatos
A1: Nome do inscrito(a) | B1: Data de inscrição | C1: e-mail | D1: Contato | E1: Região | F1: Turma | G1: Idade | H1: Renda Familiar | I1: Equipe NAU | J1: Agendamento | K1: Status | L1: Motivo | M1: Comentarios
A2: =Database!B2 | B2: =Database!A2 | C2: =Database!D2 | D2: =Database!E2 | E2: =Database!F2 | F2: =Database!G2 | G2: =Database!C2 | H2: =Database!H2
A3: =Database!B3 | B3: =Database!A3 | C3: =Database!D3 | D3: =Database!E3 | E3: =Database!F3 | F3: =Database!G3 | G3: =Database!C3 | H3: =Database!H3
A4: =Database!B4 | B4: =Database!A4 | C4: =Database!D4 | D4: =Database!E4 | E4: =Database!F4 | F4: =Database!G4 | G4: =Database!C4 | H4: =Database!H4
A5: =Database!B5 | B5: =Database!A5 | C5: =Database!D5 | D5: =Database!E5 | E5: =Database!F5 | F5: =Database!G5 | G5: =Database!C5 | H5: =Database!H5
A6: =Database!B6 | B6: =Database!A6 | C6: =Database!D6 | D6: =Database!E6 | E6: =Database!F6 | F6: =Database!G6 | G6: =Database!C6 | H6: =Database!H6
A7: =Database!B7 | B7: =Database!A7 | C7: =Database!D7 | D7: =Database!E7 | E7: =Database!F7 | F7: =Database!G7 | G7: =Database!C7 | H7: =Database!H7
A8: =Database!B8 | B8: =Database!A8 | C8: =Database!D8 | D8: =Database!E8 | E8: =Database!F8 | F8: =Database!G8 | G8: =Database!C8 | H8: =Database!H8
A9: =Database!B9 | B9: =Database!A9 | C9: =Database!D9 | D9: =Database!E9 | E9: =Database!F9 | F9: =Database!G9 | G9: =Database!C9 | H9: =Database!H9
A10: =Database!B10 | B10: =Database!A10 | C10: =Database!D10 | D10: =Database!E10 | E10: =Database!F10 | F10: =Database!G10 | G10: =Database!C10 | H10: =Database!H10
A11: =Database!B11 | B11: =Database!A11 | C11: =Database!D11 | D11: =Database!E11 | E11: =Database!F11 | F11: =Database!G11 | G11: =Database!C11 | H11: =Database!H11
A12: =Database!B12 | B12: =Database!A12 | C12: =Database!D12 | D12: =Database!E12 | E12: =Database!F12 | F12: =Database!G12 | G12: =Database!C12 | H12: =Database!H12
A13: =Database!B13 | B13: =Database!A13 | C13: =Database!D13 | D13: =Database!E13 | E13: =Database!F13 | F13: =Database!G13 | G13: =Database!C13 | H13: =Database!H13
... A25: =Database!B25 | B25: =Database!A25 | C25: =Database!D25 | D25: =Database!E25 | E25: =Database!F25 | F25: =Database!G25 | G25: =Database!C25 | H25: =Database!H25
A26: =Database!B26 | B26: =Database!A26 | C26: =Database!D26 | D26: =Database!E26 | E26: =Database!F26 | F26: =Database!G26 | G26: =Database!C26 | H26: =Database!H26 | P26: 45852
A27: =Database!B27 | B27: =Database!A27 | C27: =Database!D27 | D27: =Database!E27 | E27: =Database!F27 | F27: =Database!G27 | G27: =Database!C27 | H27: =Database!H27
A28: =Database!B28 | B28: =Database!A28 | C28: =Database!D28 | D28: =Database!E28 | E28: =Database!F28 | F28: =Database!G28 | G28: =Database!C28 | H28: =Database!H28
A29: =Database!B29 | B29: =Database!A29 | C29: =Database!D29 | D29: =Database!E29 | E29: =Database!F29 | F29: =Database!G29 | G29: =Database!C29 | H29: =Database!H29
A30: =Database!B30 | B30: =Database!A30 | C30: =Database!D30 | D30: =Database!E30 | E30: =Database!F30 | F30: =Database!G30 | G30: =Database!C30 | H30: =Database!H30
A31: =Database!B31 | B31: =Database!A31 | C31: =Database!D31 | D31: =Database!E31 | E31: =Database!F31 | F31: =Database!G31 | G31: =Database!C31 | H31: =Database!H31
A32: =Database!B32 | B32: =Database!A32 | C32: =Database!D32 | D32: =Database!E32 | E32: =Database!F32 | F32: =Database!G32 | G32: =Database!C32 | H32: =Database!H32
A33: =Database!B33 | B33: =Database!A33 | C33: =Database!D33 | D33: =Database!E33 | E33: =Database!F33 | F33: =Database!G33 | G33: =Database!C33 | H33: =Database!H33
A34: =Database!B34 | B34: =Database!A34 | C34: =Database!D34 | D34: =Database!E34 | E34: =Database!F34 | F34: =Database!G34 | G34: =Database!C34 | H34: =Database!H34
A35: =Database!B35 | B35: =Database!A35 | C35: =Database!D35 | D35: =Database!E35 | E35: =Database!F35 | F35: =Database!G35 | G35: =Database!C35 | H35: =Database!H35
A36: =Database!B36 | B36: =Database!A36 | C36: =Database!D36 | D36: =Database!E36 | E36: =Database!F36 | F36: =Database!G36 | G36: =Database!C36 | H36: =Database!H36
A37: =Database!B37 | B37: =Database!A37 | C37: =Database!D37 | D37: =Database!E37 | E37: =Database!F37 | F37: =Database!G37 | G37: =Database!C37 | H37: =Database!H37
A38: =Database!B38 | B38: =Database!A38 | C38: =Database!D38 | D38: =Database!E38 | E38: =Database!F38 | F38: =Database!G38 | G38: =Database!C38 | H38: =Database!H38
... A758: =Database!B758 | B758: =Database!A758 | C758: =Database!D758 | D758: =Database!E758 | E758: =Database!F758 | F758: =Database!G758 | G758: =Database!C758 | H758: =Database!H758
A759: =Database!B759 | B759: =Database!A759 | C759: =Database!D759 | D759: =Database!E759 | F759: =Database!G759 | G759: =Database!C759 | H759: =Database!H759
A760: =Database!B760 | B760: =Database!A760 | C760: =Database!D760 | D760: =Database!E760 | F760: =Database!G760 | G760: =Database!C760 | H760: =Database!H760
A761: =Database!B761 | B761: =Database!A761 | C761: =Database!D761 | D761: =Database!E761 | F761: =Database!G761 | G761: =Database!C761 | H761: =Database!H761
A762: =Database!B762 | B762: =Database!A762 | C762: =Database!D762 | D762: =Database!E762 | F762: =Database!G762 | G762: =Database!C762 | H762: =Database!H762
A763: =Database!B763 | B763: =Database!A763 | C763: =Database!D763 | D763: =Database!E763 | F763: =Database!G763 | G763: =Database!C763 | H763: =Database!H763
A764: =Database!B764 | B764: =Database!A764 | C764: =Database!D764 | D764: =Database!E764 | G764: =Database!C764 | H764: =Database!H764
A765: =Database!B765 | B765: =Database!A765 | C765: =Database!D765 | D765: =Database!E765 | G765: =Database!C765 | H765: =Database!H765
A766: =Database!B766 | B766: =Database!A766 | C766: =Database!D766 | D766: =Database!E766 | G766: =Database!C766 | H766: =Database!H766
A767: =Database!B767 | B767: =Database!A767 | C767: =Database!D767 | D767: =Database!E767 | H767: =Database!H767
A768: =Database!B768 | B768: =Database!A768 | C768: =Database!D768 | D768: =Database!E768 | H768: =Database!H768
A769: =Database!B769 | B769: =Database!A769 | C769: =Database!D769 | D769: =Database!E769 | H769: =Database!H769
A770: =Database!B770 | B770: =Database!A770 | C770: =Database!D770 | D770: =Database!E770 | H770: =Database!H770
...

Sheet Aprovados
A1: Nome do inscrito(a) | B1: Data de inscrição | C1: e-mail | D1: Contato | E1: Região | F1: Turma | G1: Idade | H1: Renda Familiar | I1: Equipe NAU | J1: Agendamento | K1: Motivo | L1: Comentarios
A2: =IF(Candidatos!$K2="Aprovado",Candidatos!A2,"") | B2: =IF(Candidatos!$K2="Aprovado",Candidatos!B2,"") | C2: =IF(Candidatos!$K2="Aprovado",Candidatos!C2,"") | D2: =IF(Candidatos!$K2="Aprovado",Candidatos!D2,"") | E2: =IF(Candidatos!$K2="Aprovado",Candidatos!E2,"") | F2: =IF(Candidatos!$K2="Aprovado",Candidatos!F2,"") | G2: =IF(Candidatos!$K2="Aprovado",Database!C2,"") | H2: =IF(Candidatos!$K2="Aprovado",Candidatos!H2,"") | I2: =IF(Candidatos!$K2="Aprovado",Candidatos!I2,"") | J2: =IF(Candidatos!$K2="Aprovado",Candidatos!J2,"") | K2: =IF(Candidatos!$K2="Aprovado",Candidatos!L2,"") | L2: =IF(Candidatos!$K2="Aprovado",Candidatos!M2,"")
A3: =IF(Candidatos!$K3="Aprovado",Candidatos!A3,"") | B3: =IF(Candidatos!$K3="Aprovado",Candidatos!B3,"") | C3: =IF(Candidatos!$K3="Aprovado",Candidatos!C3,"") | D3: =IF(Candidatos!$K3="Aprovado",Candidatos!D3,"") | E3: =IF(Candidatos!$K3="Aprovado",Candidatos!E3,"") | F3: =IF(Candidatos!$K3="Aprovado",Candidatos!F3,"") | G3: =IF(Candidatos!$K3="Aprovado",Database!C3,"") | H3: =IF(Candidatos!$K3="Aprovado",Candidatos!H3,"") | I3: =IF(Candidatos!$K3="Aprovado",Candidatos!I3,"") | J3: =IF(Candidatos!$K3="Aprovado",Candidatos!J3,"") | K3: =IF(Candidatos!$K3="Aprovado",Candidatos!L3,"") | L3: =IF(Candidatos!$K3="Aprovado",Candidatos!M3,"")
A4: =IF(Candidatos!$K4="Aprovado",Candidatos!A4,"") | B4: =IF(Candidatos!$K4="Aprovado",Candidatos!B4,"") | C4: =IF(Candidatos!$K4="Aprovado",Candidatos!C4,"") | D4: =IF(Candidatos!$K4="Aprovado",Candidatos!D4,"") | E4: =IF(Candidatos!$K4="Aprovado",Candidatos!E4,"") | F4: =IF(Candidatos!$K4="Aprovado",Candidatos!F4,"") | G4: =IF(Candidatos!$K4="Aprovado",Database!C4,"") | H4: =IF(Candidatos!$K4="Aprovado",Candidatos!H4,"") | I4: =IF(Candidatos!$K4="Aprovado",Candidatos!I4,"") | J4: =IF(Candidatos!$K4="Aprovado",Candidatos!J4,"") | K4: =IF(Candidatos!$K4="Aprovado",Candidatos!L4,"") | L4: =IF(Candidatos!$K4="Aprovado",Candidatos!M4,"")
A5: =IF(Candidatos!$K5="Aprovado",Candidatos!A5,"") | B5: =IF(Candidatos!$K5="Aprovado",Candidatos!B5,"") | C5: =IF(Candidatos!$K5="Aprovado",Candidatos!C5,"") | D5: =IF(Candidatos!$K5="Aprovado",Candidatos!D5,"") | E5: =IF(Candidatos!$K5="Aprovado",Candidatos!E5,"") | F5: =IF(Candidatos!$K5="Aprovado",Candidatos!F5,"") | G5: =IF(Candidatos!$K5="Aprovado",Database!C5,"") | H5: =IF(Candidatos!$K5="Aprovado",Candidatos!H5,"") | I5: =IF(Candidatos!$K5="Aprovado",Candidatos!I5,"") | J5: =IF(Candidatos!$K5="Aprovado",Candidatos!J5,"") | K5: =IF(Candidatos!$K5="Aprovado",Candidatos!L5,"") | L5: =IF(Candidatos!$K5="Aprovado",Candidatos!M5,"")
A6: =IF(Candidatos!$K6="Aprovado",Candidatos!A6,"") | B6: =IF(Candidatos!$K6="Aprovado",Candidatos!B6,"") | C6: =IF(Candidatos!$K6="Aprovado",Candidatos!C6,"") | D6: =IF(Candidatos!$K6="Aprovado",Candidatos!D6,"") | E6: =IF(Candidatos!$K6="Aprovado",Candidatos!E6,"") | F6: =IF(Candidatos!$K6="Aprovado",Candidatos!F6,"") | G6: =IF(Candidatos!$K6="Aprovado",Database!C6,"") | H6: =IF(Candidatos!$K6="Aprovado",Candidatos!H6,"") | I6: =IF(Candidatos!$K6="Aprovado",Candidatos!I6,"") | J6: =IF(Candidatos!$K6="Aprovado",Candidatos!J6,"") | K6: =IF(Candidatos!$K6="Aprovado",Candidatos!L6,"") | L6: =IF(Candidatos!$K6="Aprovado",Candidatos!M6,"")
A7: =IF(Candidatos!$K7="Aprovado",Candidatos!A7,"") | B7: =IF(Candidatos!$K7="Aprovado",Candidatos!B7,"") | C7: =IF(Candidatos!$K7="Aprovado",Candidatos!C7,"") | D7: =IF(Candidatos!$K7="Aprovado",Candidatos!D7,"") | E7: =IF(Candidatos!$K7="Aprovado",Candidatos!E7,"") | F7: =IF(Candidatos!$K7="Aprovado",Candidatos!F7,"") | G7: =IF(Candidatos!$K7="Aprovado",Database!C7,"") | H7: =IF(Candidatos!$K7="Aprovado",Candidatos!H7,"") | I7: =IF(Candidatos!$K7="Aprovado",Candidatos!I7,"") | J7: =IF(Candidatos!$K7="Aprovado",Candidatos!J7,"") | K7: =IF(Candidatos!$K7="Aprovado",Candidatos!L7,"") | L7: =IF(Candidatos!$K7="Aprovado",Candidatos!M7,"")
A8: =IF(Candidatos!$K8="Aprovado",Candidatos!A8,"") | B8: =IF(Candidatos!$K8="Aprovado",Candidatos!B8,"") | C8: =IF(Candidatos!$K8="Aprovado",Candidatos!C8,"") | D8: =IF(Candidatos!$K8="Aprovado",Candidatos!D8,"") | E8: =IF(Candidatos!$K8="Aprovado",Candidatos!E8,"") | F8: =IF(Candidatos!$K8="Aprovado",Candidatos!F8,"") | G8: =IF(Candidatos!$K8="Aprovado",Database!C8,"") | H8: =IF(Candidatos!$K8="Aprovado",Candidatos!H8,"") | I8: =IF(Candidatos!$K8="Aprovado",Candidatos!I8,"") | J8: =IF(Candidatos!$K8="Aprovado",Candidatos!J8,"") | K8: =IF(Candidatos!$K8="Aprovado",Candidatos!L8,"") | L8: =IF(Candidatos!$K8="Aprovado",Candidatos!M8,"")
A9: =IF(Candidatos!$K9="Aprovado",Candidatos!A9,"") | B9: =IF(Candidatos!$K9="Aprovado",Candidatos!B9,"") | C9: =IF(Candidatos!$K9="Aprovado",Candidatos!C9,"") | D9: =IF(Candidatos!$K9="Aprovado",Candidatos!D9,"") | E9: =IF(Candidatos!$K9="Aprovado",Candidatos!E9,"") | F9: =IF(Candidatos!$K9="Aprovado",Candidatos!F9,"") | G9: =IF(Candidatos!$K9="Aprovado",Database!C9,"") | H9: =IF(Candidatos!$K9="Aprovado",Candidatos!H9,"") | I9: =IF(Candidatos!$K9="Aprovado",Candidatos!I9,"") | J9: =IF(Candidatos!$K9="Aprovado",Candidatos!J9,"") | K9: =IF(Candidatos!$K9="Aprovado",Candidatos!L9,"") | L9: =IF(Candidatos!$K9="Aprovado",Candidatos!M9,"")
A10: =IF(Candidatos!$K10="Aprovado",Candidatos!A10,"") | B10: =IF(Candidatos!$K10="Aprovado",Candidatos!B10,"") | C10: =IF(Candidatos!$K10="Aprovado",Candidatos!C10,"") | D10: =IF(Candidatos!$K10="Aprovado",Candidatos!D10,"") | E10: =IF(Candidatos!$K10="Aprovado",Candidatos!E10,"") | F10: =IF(Candidatos!$K10="Aprovado",Candidatos!F10,"") | G10: =IF(Candidatos!$K10="Aprovado",Database!C10,"") | H10: =IF(Candidatos!$K10="Aprovado",Candidatos!H10,"") | I10: =IF(Candidatos!$K10="Aprovado",Candidatos!I10,"") | J10: =IF(Candidatos!$K10="Aprovado",Candidatos!J10,"") | K10: =IF(Candidatos!$K10="Aprovado",Candidatos!L10,"") | L10: =IF(Candidatos!$K10="Aprovado",Candidatos!M10,"")
A11: =IF(Candidatos!$K11="Aprovado",Candidatos!A11,"") | B11: =IF(Candidatos!$K11="Aprovado",Candidatos!B11,"") | C11: =IF(Candidatos!$K11="Aprovado",Candidatos!C11,"") | D11: =IF(Candidatos!$K11="Aprovado",Candidatos!D11,"") | E11: =IF(Candidatos!$K11="Aprovado",Candidatos!E11,"") | F11: =IF(Candidatos!$K11="Aprovado",Candidatos!F11,"") | G11: =IF(Candidatos!$K11="Aprovado",Database!C11,"") | H11: =IF(Candidatos!$K11="Aprovado",Candidatos!H11,"") | I11: =IF(Candidatos!$K11="Aprovado",Candidatos!I11,"") | J11: =IF(Candidatos!$K11="Aprovado",Candidatos!J11,"") | K11: =IF(Candidatos!$K11="Aprovado",Candidatos!L11,"") | L11: =IF(Candidatos!$K11="Aprovado",Candidatos!M11,"")
A12: =IF(Candidatos!$K12="Aprovado",Candidatos!A12,"") | B12: =IF(Candidatos!$K12="Aprovado",Candidatos!B12,"") | C12: =IF(Candidatos!$K12="Aprovado",Candidatos!C12,"") | D12: =IF(Candidatos!$K12="Aprovado",Candidatos!D12,"") | E12: =IF(Candidatos!$K12="Aprovado",Candidatos!E12,"") | F12: =IF(Candidatos!$K12="Aprovado",Candidatos!F12,"") | G12: =IF(Candidatos!$K12="Aprovado",Database!C12,"") | H12: =IF(Candidatos!$K12="Aprovado",Candidatos!H12,"") | I12: =IF(Candidatos!$K12="Aprovado",Candidatos!I12,"") | J12: =IF(Candidatos!$K12="Aprovado",Candidatos!J12,"") | K12: =IF(Candidatos!$K12="Aprovado",Candidatos!L12,"") | L12: =IF(Candidatos!$K12="Aprovado",Candidatos!M12,"")
A13: =IF(Candidatos!$K13="Aprovado",Candidatos!A13,"") | B13: =IF(Candidatos!$K13="Aprovado",Candidatos!B13,"") | C13: =IF(Candidatos!$K13="Aprovado",Candidatos!C13,"") | D13: =IF(Candidatos!$K13="Aprovado",Candidatos!D13,"") | E13: =IF(Candidatos!$K13="Aprovado",Candidatos!E13,"") | F13: =IF(Candidatos!$K13="Aprovado",Candidatos!F13,"") | G13: =IF(Candidatos!$K13="Aprovado",Database!C13,"") | H13: =IF(Candidatos!$K13="Aprovado",Candidatos!H13,"") | I13: =IF(Candidatos!$K13="Aprovado",Candidatos!I13,"") | J13: =IF(Candidatos!$K13="Aprovado",Candidatos!J13,"") | K13: =IF(Candidatos!$K13="Aprovado",Candidatos!L13,"") | L13: =IF(Candidatos!$K13="Aprovado",Candidatos!M13,"")
... A281: =IF(Candidatos!$K281="Aprovado",Candidatos!A281,"") | B281: =IF(Candidatos!$K281="Aprovado",Candidatos!B281,"") | C281: =IF(Candidatos!$K281="Aprovado",Candidatos!C281,"") | D281: =IF(Candidatos!$K281="Aprovado",Candidatos!D281,"") | E281: =IF(Candidatos!$K281="Aprovado",Candidatos!E281,"") | F281: =IF(Candidatos!$K281="Aprovado",Candidatos!F281,"") | G281: =IF(Candidatos!$K281="Aprovado",Database!C281,"") | H281: =IF(Candidatos!$K281="Aprovado",Candidatos!H281,"") | I281: =IF(Candidatos!$K281="Aprovado",Candidatos!I281,"") | J281: =IF(Candidatos!$K281="Aprovado",Candidatos!J281,"") | K281: =IF(Candidatos!$K281="Aprovado",Candidatos!L281,"") | L281: =IF(Candidatos!$K281="Aprovado",Candidatos!M281,"")
A282: =IF(Candidatos!$K282="Aprovado",Candidatos!A282,"") | B282: =IF(Candidatos!$K282="Aprovado",Candidatos!B282,"") | C282: =IF(Candidatos!$K282="Aprovado",Candidatos!C282,"") | D282: =IF(Candidatos!$K282="Aprovado",Candidatos!D282,"") | E282: =IF(Candidatos!$K282="Aprovado",Candidatos!E282,"") | F282: =IF(Candidatos!$K282="Aprovado",Candidatos!F282,"") | G282: =IF(Candidatos!$K282="Aprovado",Database!C282,"") | H282: =IF(Candidatos!$K282="Aprovado",Candidatos!H282,"") | I282: =IF(Candidatos!$K282="Aprovado",Candidatos!I283,"") | J282: =IF(Candidatos!$K282="Aprovado",Candidatos!J282,"") | K282: =IF(Candidatos!$K282="Aprovado",Candidatos!L282,"") | L282: =IF(Candidatos!$K282="Aprovado",Candidatos!M282,"")
A283: =IF(Candidatos!$K283="Aprovado",Candidatos!A283,"") | B283: =IF(Candidatos!$K283="Aprovado",Candidatos!B283,"") | C283: =IF(Candidatos!$K283="Aprovado",Candidatos!C283,"") | D283: =IF(Candidatos!$K283="Aprovado",Candidatos!D283,"") | E283: =IF(Candidatos!$K283="Aprovado",Candidatos!E283,"") | F283: =IF(Candidatos!$K283="Aprovado",Candidatos!F283,"") | G283: =IF(Candidatos!$K283="Aprovado",Database!C283,"") | H283: =IF(Candidatos!$K283="Aprovado",Candidatos!H283,"") | I283: =IF(Candidatos!$K283="Aprovado",#REF!,"") | J283: =IF(Candidatos!$K283="Aprovado",Candidatos!J283,"") | K283: =IF(Candidatos!$K283="Aprovado",Candidatos!L283,"") | L283: =IF(Candidatos!$K283="Aprovado",Candidatos!M283,"")
A284: =IF(Candidatos!$K284="Aprovado",Candidatos!A284,"") | B284: =IF(Candidatos!$K284="Aprovado",Candidatos!B284,"") | C284: =IF(Candidatos!$K284="Aprovado",Candidatos!C284,"") | D284: =IF(Candidatos!$K284="Aprovado",Candidatos!D284,"") | E284: =IF(Candidatos!$K284="Aprovado",Candidatos!E284,"") | F284: =IF(Candidatos!$K284="Aprovado",Candidatos!F284,"") | G284: =IF(Candidatos!$K284="Aprovado",Database!C284,"") | H284: =IF(Candidatos!$K284="Aprovado",Candidatos!H284,"") | I284: =IF(Candidatos!$K284="Aprovado",Candidatos!I284,"") | J284: =IF(Candidatos!$K284="Aprovado",Candidatos!J284,"") | K284: =IF(Candidatos!$K284="Aprovado",Candidatos!L284,"") | L284: =IF(Candidatos!$K284="Aprovado",Candidatos!M284,"")
A285: =IF(Candidatos!$K285="Aprovado",Candidatos!A285,"") | B285: =IF(Candidatos!$K285="Aprovado",Candidatos!B285,"") | C285: =IF(Candidatos!$K285="Aprovado",Candidatos!C285,"") | D285: =IF(Candidatos!$K285="Aprovado",Candidatos!D285,"") | E285: =IF(Candidatos!$K285="Aprovado",Candidatos!E285,"") | F285: =IF(Candidatos!$K285="Aprovado",Candidatos!F285,"") | G285: =IF(Candidatos!$K285="Aprovado",Database!C285,"") | H285: =IF(Candidatos!$K285="Aprovado",Candidatos!H285,"") | I285: =IF(Candidatos!$K285="Aprovado",Candidatos!I285,"") | J285: =IF(Candidatos!$K285="Aprovado",Candidatos!J285,"") | K285: =IF(Candidatos!$K285="Aprovado",Candidatos!L285,"") | L285: =IF(Candidatos!$K285="Aprovado",Candidatos!M285,"")
A286: =IF(Candidatos!$K286="Aprovado",Candidatos!A286,"") | B286: =IF(Candidatos!$K286="Aprovado",Candidatos!B286,"") | C286: =IF(Candidatos!$K286="Aprovado",Candidatos!C286,"") | D286: =IF(Candidatos!$K286="Aprovado",Candidatos!D286,"") | E286: =IF(Candidatos!$K286="Aprovado",Candidatos!E286,"") | F286: =IF(Candidatos!$K286="Aprovado",Candidatos!F286,"") | G286: =IF(Candidatos!$K286="Aprovado",Database!C286,"") | H286: =IF(Candidatos!$K286="Aprovado",Candidatos!H286,"") | I286: =IF(Candidatos!$K286="Aprovado",Candidatos!I286,"") | J286: =IF(Candidatos!$K286="Aprovado",Candidatos!J286,"") | K286: =IF(Candidatos!$K286="Aprovado",Candidatos!L286,"") | L286: =IF(Candidatos!$K286="Aprovado",Candidatos!M286,"")
A287: =IF(Candidatos!$K287="Aprovado",Candidatos!A287,"") | B287: =IF(Candidatos!$K287="Aprovado",Candidatos!B287,"") | C287: =IF(Candidatos!$K287="Aprovado",Candidatos!C287,"") | D287: =IF(Candidatos!$K287="Aprovado",Candidatos!D287,"") | E287: =IF(Candidatos!$K287="Aprovado",Candidatos!E287,"") | F287: =IF(Candidatos!$K287="Aprovado",Candidatos!F287,"") | G287: =IF(Candidatos!$K287="Aprovado",Database!C287,"") | H287: =IF(Candidatos!$K287="Aprovado",Candidatos!H287,"") | I287: =IF(Candidatos!$K287="Aprovado",Candidatos!I287,"") | J287: =IF(Candidatos!$K287="Aprovado",Candidatos!J287,"") | K287: =IF(Candidatos!$K287="Aprovado",Candidatos!L287,"") | L287: =IF(Candidatos!$K287="Aprovado",Candidatos!M287,"")
A288: =IF(Candidatos!$K288="Aprovado",Candidatos!A288,"") | B288: =IF(Candidatos!$K288="Aprovado",Candidatos!B288,"") | C288: =IF(Candidatos!$K288="Aprovado",Candidatos!C288,"") | D288: =IF(Candidatos!$K288="Aprovado",Candidatos!D288,"") | E288: =IF(Candidatos!$K288="Aprovado",Candidatos!E288,"") | F288: =IF(Candidatos!$K288="Aprovado",Candidatos!F288,"") | G288: =IF(Candidatos!$K288="Aprovado",Database!C288,"") | H288: =IF(Candidatos!$K288="Aprovado",Candidatos!H288,"") | I288: =IF(Candidatos!$K288="Aprovado",Candidatos!I288,"") | J288: =IF(Candidatos!$K288="Aprovado",Candidatos!J288,"") | K288: =IF(Candidatos!$K288="Aprovado",Candidatos!L288,"") | L288: =IF(Candidatos!$K288="Aprovado",Candidatos!M288,"")
A289: =IF(Candidatos!$K289="Aprovado",Candidatos!A289,"") | B289: =IF(Candidatos!$K289="Aprovado",Candidatos!B289,"") | C289: =IF(Candidatos!$K289="Aprovado",Candidatos!C289,"") | D289: =IF(Candidatos!$K289="Aprovado",Candidatos!D289,"") | E289: =IF(Candidatos!$K289="Aprovado",Candidatos!E289,"") | F289: =IF(Candidatos!$K289="Aprovado",Candidatos!F289,"") | G289: =IF(Candidatos!$K289="Aprovado",Database!C289,"") | H289: =IF(Candidatos!$K289="Aprovado",Candidatos!H289,"") | I289: =IF(Candidatos!$K289="Aprovado",Candidatos!I289,"") | J289: =IF(Candidatos!$K289="Aprovado",Candidatos!J289,"") | K289: =IF(Candidatos!$K289="Aprovado",Candidatos!L289,"") | L289: =IF(Candidatos!$K289="Aprovado",Candidatos!M289,"")
A290: =IF(Candidatos!$K290="Aprovado",Candidatos!A290,"") | B290: =IF(Candidatos!$K290="Aprovado",Candidatos!B290,"") | C290: =IF(Candidatos!$K290="Aprovado",Candidatos!C290,"") | D290: =IF(Candidatos!$K290="Aprovado",Candidatos!D290,"") | E290: =IF(Candidatos!$K290="Aprovado",Candidatos!E290,"") | F290: =IF(Candidatos!$K290="Aprovado",Candidatos!F290,"") | G290: =IF(Candidatos!$K290="Aprovado",Database!C290,"") | H290: =IF(Candidatos!$K290="Aprovado",Candidatos!H290,"") | I290: =IF(Candidatos!$K290="Aprovado",Candidatos!I290,"") | J290: =IF(Candidatos!$K290="Aprovado",Candidatos!J290,"") | K290: =IF(Candidatos!$K290="Aprovado",Candidatos!L290,"") | L290: =IF(Candidatos!$K290="Aprovado",Candidatos!M290,"")
A291: =IF(Candidatos!$K291="Aprovado",Candidatos!A291,"") | B291: =IF(Candidatos!$K291="Aprovado",Candidatos!B291,"") | C291: =IF(Candidatos!$K291="Aprovado",Candidatos!C291,"") | D291: =IF(Candidatos!$K291="Aprovado",Candidatos!D291,"") | E291: =IF(Candidatos!$K291="Aprovado",Candidatos!E291,"") | F291: =IF(Candidatos!$K291="Aprovado",Candidatos!F291,"") | G291: =IF(Candidatos!$K291="Aprovado",Database!C291,"") | H291: =IF(Candidatos!$K291="Aprovado",Candidatos!H291,"") | I291: =IF(Candidatos!$K291="Aprovado",Candidatos!I291,"") | J291: =IF(Candidatos!$K291="Aprovado",Candidatos!J291,"") | K291: =IF(Candidatos!$K291="Aprovado",Candidatos!L291,"") | L291: =IF(Candidatos!$K291="Aprovado",Candidatos!M291,"")
A292: =IF(Candidatos!$K292="Aprovado",Candidatos!A292,"") | B292: =IF(Candidatos!$K292="Aprovado",Candidatos!B292,"") | C292: =IF(Candidatos!$K292="Aprovado",Candidatos!C292,"") | D292: =IF(Candidatos!$K292="Aprovado",Candidatos!D292,"") | E292: =IF(Candidatos!$K292="Aprovado",Candidatos!E292,"") | F292: =IF(Candidatos!$K292="Aprovado",Candidatos!F292,"") | G292: =IF(Candidatos!$K292="Aprovado",Database!C292,"") | H292: =IF(Candidatos!$K292="Aprovado",Candidatos!H292,"") | I292: =IF(Candidatos!$K292="Aprovado",Candidatos!I292,"") | J292: =IF(Candidatos!$K292="Aprovado",Candidatos!J292,"") | K292: =IF(Candidatos!$K292="Aprovado",Candidatos!L292,"") | L292: =IF(Candidatos!$K292="Aprovado",Candidatos!M292,"")
A293: =IF(Candidatos!$K293="Aprovado",Candidatos!A293,"") | B293: =IF(Candidatos!$K293="Aprovado",Candidatos!B293,"") | C293: =IF(Candidatos!$K293="Aprovado",Candidatos!C293,"") | D293: =IF(Candidatos!$K293="Aprovado",Candidatos!D293,"") | E293: =IF(Candidatos!$K293="Aprovado",Candidatos!E293,"") | F293: =IF(Candidatos!$K293="Aprovado",Candidatos!F293,"") | G293: =IF(Candidatos!$K293="Aprovado",Database!C293,"") | H293: =IF(Candidatos!$K293="Aprovado",Candidatos!H293,"") | I293: =IF(Candidatos!$K293="Aprovado",Candidatos!I293,"") | J293: =IF(Candidatos!$K293="Aprovado",Candidatos!J293,"") | K293: =IF(Candidatos!$K293="Aprovado",Candidatos!L293,"") | L293: =IF(Candidatos!$K293="Aprovado",Candidatos!M293,"")
A294: =IF(Candidatos!$K294="Aprovado",Candidatos!A294,"") | B294: =IF(Candidatos!$K294="Aprovado",Candidatos!B294,"") | C294: =IF(Candidatos!$K294="Aprovado",Candidatos!C294,"") | D294: =IF(Candidatos!$K294="Aprovado",Candidatos!D294,"") | E294: =IF(Candidatos!$K294="Aprovado",Candidatos!E294,"") | F294: =IF(Candidatos!$K294="Aprovado",Candidatos!F294,"") | G294: =IF(Candidatos!$K294="Aprovado",Database!C294,"") | H294: =IF(Candidatos!$K294="Aprovado",Candidatos!H294,"") | I294: =IF(Candidatos!$K294="Aprovado",Candidatos!I294,"") | J294: =IF(Candidatos!$K294="Aprovado",Candidatos!J294,"") | K294: =IF(Candidatos!$K294="Aprovado",Candidatos!L294,"") | L294: =IF(Candidatos!$K294="Aprovado",Candidatos!M294,"")
A295: =IF(Candidatos!$K295="Aprovado",Candidatos!A295,"") | B295: =IF(Candidatos!$K295="Aprovado",Candidatos!B295,"") | C295: =IF(Candidatos!$K295="Aprovado",Candidatos!C295,"") | D295: =IF(Candidatos!$K295="Aprovado",Candidatos!D295,"") | E295: =IF(Candidatos!$K295="Aprovado",Candidatos!E295,"") | F295: =IF(Candidatos!$K295="Aprovado",Candidatos!F295,"") | G295: =IF(Candidatos!$K295="Aprovado",Database!C295,"") | H295: =IF(Candidatos!$K295="Aprovado",Candidatos!H295,"") | I295: =IF(Candidatos!$K295="Aprovado",Candidatos!I295,"") | J295: =IF(Candidatos!$K295="Aprovado",Candidatos!J295,"") | K295: =IF(Candidatos!$K295="Aprovado",Candidatos!L295,"") | L295: =IF(Candidatos!$K295="Aprovado",Candidatos!M295,"")
... A360: =IF(Candidatos!$K360="Aprovado",Candidatos!A360,"") | B360: =IF(Candidatos!$K360="Aprovado",Candidatos!B360,"") | C360: =IF(Candidatos!$K360="Aprovado",Candidatos!C360,"") | D360: =IF(Candidatos!$K360="Aprovado",Candidatos!D360,"") | E360: =IF(Candidatos!$K360="Aprovado",Candidatos!E360,"") | F360: =IF(Candidatos!$K360="Aprovado",Candidatos!F360,"") | G360: =IF(Candidatos!$K360="Aprovado",Database!C360,"") | H360: =IF(Candidatos!$K360="Aprovado",Candidatos!H360,"") | I360: =IF(Candidatos!$K360="Aprovado",Candidatos!I360,"") | J360: =IF(Candidatos!$K360="Aprovado",Candidatos!J360,"") | K360: =IF(Candidatos!$K360="Aprovado",Candidatos!L360,"") | L360: =IF(Candidatos!$K360="Aprovado",Candidatos!M360,"")
A361: =IF(Candidatos!$K361="Aprovado",Candidatos!A361,"") | B361: =IF(Candidatos!$K361="Aprovado",Candidatos!B361,"") | C361: =IF(Candidatos!$K361="Aprovado",Candidatos!C361,"") | D361: =IF(Candidatos!$K361="Aprovado",Candidatos!D361,"") | E361: =IF(Candidatos!$K361="Aprovado",Candidatos!E361,"") | F361: =IF(Candidatos!$K361="Aprovado",Candidatos!F361,"") | G361: =IF(Candidatos!$K361="Aprovado",Database!C361,"") | H361: =IF(Candidatos!$K361="Aprovado",Candidatos!H361,"") | I361: =IF(Candidatos!$K361="Aprovado",#REF!,"") | J361: =IF(Candidatos!$K361="Aprovado",Candidatos!J361,"") | K361: =IF(Candidatos!$K361="Aprovado",Candidatos!L361,"") | L361: =IF(Candidatos!$K361="Aprovado",Candidatos!M361,"")
A362: =IF(Candidatos!$K362="Aprovado",Candidatos!A362,"") | B362: =IF(Candidatos!$K362="Aprovado",Candidatos!B362,"") | C362: =IF(Candidatos!$K362="Aprovado",Candidatos!C362,"") | D362: =IF(Candidatos!$K362="Aprovado",Candidatos!D362,"") | E362: =IF(Candidatos!$K362="Aprovado",Candidatos!E362,"") | F362: =IF(Candidatos!$K362="Aprovado",Candidatos!F362,"") | G362: =IF(Candidatos!$K362="Aprovado",Database!C362,"") | H362: =IF(Candidatos!$K362="Aprovado",Candidatos!H362,"") | I362: =IF(Candidatos!$K362="Aprovado",Candidatos!I361,"") | J362: =IF(Candidatos!$K362="Aprovado",Candidatos!J362,"") | K362: =IF(Candidatos!$K362="Aprovado",Candidatos!L362,"") | L362: =IF(Candidatos!$K362="Aprovado",Candidatos!M362,"")
A363: =IF(Candidatos!$K363="Aprovado",Candidatos!A363,"") | B363: =IF(Candidatos!$K363="Aprovado",Candidatos!B363,"") | C363: =IF(Candidatos!$K363="Aprovado",Candidatos!C363,"") | D363: =IF(Candidatos!$K363="Aprovado",Candidatos!D363,"") | E363: =IF(Candidatos!$K363="Aprovado",Candidatos!E363,"") | F363: =IF(Candidatos!$K363="Aprovado",Candidatos!F363,"") | G363: =IF(Candidatos!$K363="Aprovado",Database!C363,"") | H363: =IF(Candidatos!$K363="Aprovado",Candidatos!H363,"") | I363: =IF(Candidatos!$K363="Aprovado",Candidatos!I363,"") | J363: =IF(Candidatos!$K363="Aprovado",Candidatos!J363,"") | K363: =IF(Candidatos!$K363="Aprovado",Candidatos!L363,"") | L363: =IF(Candidatos!$K363="Aprovado",Candidatos!M363,"")
A364: =IF(Candidatos!$K364="Aprovado",Candidatos!A364,"") | B364: =IF(Candidatos!$K364="Aprovado",Candidatos!B364,"") | C364: =IF(Candidatos!$K364="Aprovado",Candidatos!C364,"") | D364: =IF(Candidatos!$K364="Aprovado",Candidatos!D364,"") | E364: =IF(Candidatos!$K364="Aprovado",Candidatos!E364,"") | F364: =IF(Candidatos!$K364="Aprovado",Candidatos!F364,"") | G364: =IF(Candidatos!$K364="Aprovado",Database!C364,"") | H364: =IF(Candidatos!$K364="Aprovado",Candidatos!H364,"") | I364: =IF(Candidatos!$K364="Aprovado",Candidatos!I364,"") | J364: =IF(Candidatos!$K364="Aprovado",Candidatos!J364,"") | K364: =IF(Candidatos!$K364="Aprovado",Candidatos!L364,"") | L364: =IF(Candidatos!$K364="Aprovado",Candidatos!M364,"")
A365: =IF(Candidatos!$K365="Aprovado",Candidatos!A365,"") | B365: =IF(Candidatos!$K365="Aprovado",Candidatos!B365,"") | C365: =IF(Candidatos!$K365="Aprovado",Candidatos!C365,"") | D365: =IF(Candidatos!$K365="Aprovado",Candidatos!D365,"") | E365: =IF(Candidatos!$K365="Aprovado",Candidatos!E365,"") | F365: =IF(Candidatos!$K365="Aprovado",Candidatos!F365,"") | G365: =IF(Candidatos!$K365="Aprovado",Database!C365,"") | H365: =IF(Candidatos!$K365="Aprovado",Candidatos!H365,"") | I365: =IF(Candidatos!$K365="Aprovado",Candidatos!I365,"") | J365: =IF(Candidatos!$K365="Aprovado",Candidatos!J365,"") | K365: =IF(Candidatos!$K365="Aprovado",Candidatos!L365,"") | L365: =IF(Candidatos!$K365="Aprovado",Candidatos!M365,"")
A366: =IF(Candidatos!$K366="Aprovado",Candidatos!A366,"") | B366: =IF(Candidatos!$K366="Aprovado",Candidatos!B366,"") | C366: =IF(Candidatos!$K366="Aprovado",Candidatos!C366,"") | D366: =IF(Candidatos!$K366="Aprovado",Candidatos!D366,"") | E366: =IF(Candidatos!$K366="Aprovado",Candidatos!E366,"") | F366: =IF(Candidatos!$K366="Aprovado",Candidatos!F366,"") | G366: =IF(Candidatos!$K366="Aprovado",Database!C366,"") | H366: =IF(Candidatos!$K366="Aprovado",Candidatos!H366,"") | I366: =IF(Candidatos!$K366="Aprovado",Candidatos!I366,"") | J366: =IF(Candidatos!$K366="Aprovado",Candidatos!J366,"") | K366: =IF(Candidatos!$K366="Aprovado",Candidatos!L366,"") | L366: =IF(Candidatos!$K366="Aprovado",Candidatos!M366,"")
A367: =IF(Candidatos!$K367="Aprovado",Candidatos!A367,"") | B367: =IF(Candidatos!$K367="Aprovado",Candidatos!B367,"") | C367: =IF(Candidatos!$K367="Aprovado",Candidatos!C367,"") | D367: =IF(Candidatos!$K367="Aprovado",Candidatos!D367,"") | E367: =IF(Candidatos!$K367="Aprovado",Candidatos!E367,"") | F367: =IF(Candidatos!$K367="Aprovado",Candidatos!F367,"") | G367: =IF(Candidatos!$K367="Aprovado",Database!C367,"") | H367: =IF(Candidatos!$K367="Aprovado",Candidatos!H367,"") | I367: =IF(Candidatos!$K367="Aprovado",Candidatos!I367,"") | J367: =IF(Candidatos!$K367="Aprovado",Candidatos!J367,"") | K367: =IF(Candidatos!$K367="Aprovado",Candidatos!L367,"") | L367: =IF(Candidatos!$K367="Aprovado",Candidatos!M367,"")
A368: =IF(Candidatos!$K368="Aprovado",Candidatos!A368,"") | B368: =IF(Candidatos!$K368="Aprovado",Candidatos!B368,"") | C368: =IF(Candidatos!$K368="Aprovado",Candidatos!C368,"") | D368: =IF(Candidatos!$K368="Aprovado",Candidatos!D368,"") | E368: =IF(Candidatos!$K368="Aprovado",Candidatos!E368,"") | F368: =IF(Candidatos!$K368="Aprovado",Candidatos!F368,"") | G368: =IF(Candidatos!$K368="Aprovado",Database!C368,"") | H368: =IF(Candidatos!$K368="Aprovado",Candidatos!H368,"") | I368: =IF(Candidatos!$K368="Aprovado",Candidatos!I368,"") | J368: =IF(Candidatos!$K368="Aprovado",Candidatos!J368,"") | K368: =IF(Candidatos!$K368="Aprovado",Candidatos!L368,"") | L368: =IF(Candidatos!$K368="Aprovado",Candidatos!M368,"")
A369: =IF(Candidatos!$K369="Aprovado",Candidatos!A369,"") | B369: =IF(Candidatos!$K369="Aprovado",Candidatos!B369,"") | C369: =IF(Candidatos!$K369="Aprovado",Candidatos!C369,"") | D369: =IF(Candidatos!$K369="Aprovado",Candidatos!D369,"") | E369: =IF(Candidatos!$K369="Aprovado",Candidatos!E369,"") | F369: =IF(Candidatos!$K369="Aprovado",Candidatos!F369,"") | G369: =IF(Candidatos!$K369="Aprovado",Database!C369,"") | H369: =IF(Candidatos!$K369="Aprovado",Candidatos!H369,"") | I369: =IF(Candidatos!$K369="Aprovado",Candidatos!I369,"") | J369: =IF(Candidatos!$K369="Aprovado",Candidatos!J369,"") | K369: =IF(Candidatos!$K369="Aprovado",Candidatos!L369,"") | L369: =IF(Candidatos!$K369="Aprovado",Candidatos!M369,"")
A370: =IF(Candidatos!$K370="Aprovado",Candidatos!A370,"") | B370: =IF(Candidatos!$K370="Aprovado",Candidatos!B370,"") | C370: =IF(Candidatos!$K370="Aprovado",Candidatos!C370,"") | D370: =IF(Candidatos!$K370="Aprovado",Candidatos!D370,"") | E370: =IF(Candidatos!$K370="Aprovado",Candidatos!E370,"") | F370: =IF(Candidatos!$K370="Aprovado",Candidatos!F370,"") | G370: =IF(Candidatos!$K370="Aprovado",Database!C370,"") | H370: =IF(Candidatos!$K370="Aprovado",Candidatos!H370,"") | I370: =IF(Candidatos!$K370="Aprovado",Candidatos!I370,"") | J370: =IF(Candidatos!$K370="Aprovado",Candidatos!J370,"") | K370: =IF(Candidatos!$K370="Aprovado",Candidatos!L370,"") | L370: =IF(Candidatos!$K370="Aprovado",Candidatos!M370,"")
A371: =IF(Candidatos!$K371="Aprovado",Candidatos!A371,"") | B371: =IF(Candidatos!$K371="Aprovado",Candidatos!B371,"") | C371: =IF(Candidatos!$K371="Aprovado",Candidatos!C371,"") | D371: =IF(Candidatos!$K371="Aprovado",Candidatos!D371,"") | E371: =IF(Candidatos!$K371="Aprovado",Candidatos!E371,"") | F371: =IF(Candidatos!$K371="Aprovado",Candidatos!F371,"") | G371: =IF(Candidatos!$K371="Aprovado",Database!C371,"") | H371: =IF(Candidatos!$K371="Aprovado",Candidatos!H371,"") | I371: =IF(Candidatos!$K371="Aprovado",Candidatos!I371,"") | J371: =IF(Candidatos!$K371="Aprovado",Candidatos!J371,"") | K371: =IF(Candidatos!$K371="Aprovado",Candidatos!L371,"") | L371: =IF(Candidatos!$K371="Aprovado",Candidatos!M371,"")
...

Sheet Em análise
A1: Nome do inscrito(a) | B1: Data de inscrição | C1: e-mail | D1: Contato | E1: Região | F1: Turma | G1: Idade | H1: Renda Familiar | I1: Equipe NAU | J1: Agendamento | K1: Motivo | L1: Comentarios
A2: =IF(Candidatos!$K2="Em analise",Candidatos!A2,"") | B2: =IF(Candidatos!$K2="Em analise",Candidatos!B2,"") | C2: =IF(Candidatos!$K2="Em analise",Candidatos!C2,"") | D2: =IF(Candidatos!$K2="Em analise",Candidatos!D2,"") | E2: =IF(Candidatos!$K2="Em analise",Candidatos!E2,"") | F2: =IF(Candidatos!$K2="Em analise",Candidatos!F2,"") | G2: =IF(Candidatos!$K2="Em analise",Candidatos!G2,"") | H2: =IF(Candidatos!$K2="Em analise",Candidatos!H2,"") | ... K2: =IF(Candidatos!$K2="Em analise",Candidatos!K2,"") | L2: =IF(Candidatos!$K2="Em analise",Candidatos!M2,"")
A3: =IF(Candidatos!$K3="Em analise",Candidatos!A3,"") | B3: =IF(Candidatos!$K3="Em analise",Candidatos!B3,"") | C3: =IF(Candidatos!$K3="Em analise",Candidatos!C3,"") | D3: =IF(Candidatos!$K3="Em analise",Candidatos!D3,"") | E3: =IF(Candidatos!$K3="Em analise",Candidatos!E3,"") | F3: =IF(Candidatos!$K3="Em analise",Candidatos!F3,"") | G3: =IF(Candidatos!$K3="Em analise",Candidatos!G3,"") | H3: =IF(Candidatos!$K3="Em analise",Candidatos!H3,"") | ... K3: =IF(Candidatos!$K3="Em analise",Candidatos!K3,"") | L3: =IF(Candidatos!$K3="Em analise",Candidatos!M3,"")
A4: =IF(Candidatos!$K4="Em analise",Candidatos!A4,"") | B4: =IF(Candidatos!$K4="Em analise",Candidatos!B4,"") | C4: =IF(Candidatos!$K4="Em analise",Candidatos!C4,"") | D4: =IF(Candidatos!$K4="Em analise",Candidatos!D4,"") | E4: =IF(Candidatos!$K4="Em analise",Candidatos!E4,"") | F4: =IF(Candidatos!$K4="Em analise",Candidatos!F4,"") | G4: =IF(Candidatos!$K4="Em analise",Candidatos!G4,"") | H4: =IF(Candidatos!$K4="Em analise",Candidatos!H4,"") | ... K4: =IF(Candidatos!$K4="Em analise",Candidatos!K4,"") | L4: =IF(Candidatos!$K4="Em analise",Candidatos!M4,"")
A5: =IF(Candidatos!$K5="Em analise",Candidatos!A5,"") | B5: =IF(Candidatos!$K5="Em analise",Candidatos!B5,"") | C5: =IF(Candidatos!$K5="Em analise",Candidatos!C5,"") | D5: =IF(Candidatos!$K5="Em analise",Candidatos!D5,"") | E5: =IF(Candidatos!$K5="Em analise",Candidatos!E5,"") | F5: =IF(Candidatos!$K5="Em analise",Candidatos!F5,"") | G5: =IF(Candidatos!$K5="Em analise",Candidatos!G5,"") | H5: =IF(Candidatos!$K5="Em analise",Candidatos!H5,"") | ... K5: =IF(Candidatos!$K5="Em analise",Candidatos!K5,"") | L5: =IF(Candidatos!$K5="Em analise",Candidatos!M5,"")
A6: =IF(Candidatos!$K6="Em analise",Candidatos!A6,"") | B6: =IF(Candidatos!$K6="Em analise",Candidatos!B6,"") | C6: =IF(Candidatos!$K6="Em analise",Candidatos!C6,"") | D6: =IF(Candidatos!$K6="Em analise",Candidatos!D6,"") | E6: =IF(Candidatos!$K6="Em analise",Candidatos!E6,"") | F6: =IF(Candidatos!$K6="Em analise",Candidatos!F6,"") | G6: =IF(Candidatos!$K6="Em analise",Candidatos!G6,"") | H6: =IF(Candidatos!$K6="Em analise",Candidatos!H6,"") | ... K6: =IF(Candidatos!$K6="Em analise",Candidatos!K6,"") | L6: =IF(Candidatos!$K6="Em analise",Candidatos!M6,"")
A7: =IF(Candidatos!$K7="Em analise",Candidatos!A7,"") | B7: =IF(Candidatos!$K7="Em analise",Candidatos!B7,"") | C7: =IF(Candidatos!$K7="Em analise",Candidatos!C7,"") | D7: =IF(Candidatos!$K7="Em analise",Candidatos!D7,"") | E7: =IF(Candidatos!$K7="Em analise",Candidatos!E7,"") | F7: =IF(Candidatos!$K7="Em analise",Candidatos!F7,"") | G7: =IF(Candidatos!$K7="Em analise",Candidatos!G7,"") | H7: =IF(Candidatos!$K7="Em analise",Candidatos!H7,"") | ... K7: =IF(Candidatos!$K7="Em analise",Candidatos!K7,"") | L7: =IF(Candidatos!$K7="Em analise",Candidatos!M7,"")
A8: =IF(Candidatos!$K8="Em analise",Candidatos!A8,"") | B8: =IF(Candidatos!$K8="Em analise",Candidatos!B8,"") | C8: =IF(Candidatos!$K8="Em analise",Candidatos!C8,"") | D8: =IF(Candidatos!$K8="Em analise",Candidatos!D8,"") | E8: =IF(Candidatos!$K8="Em analise",Candidatos!E8,"") | F8: =IF(Candidatos!$K8="Em analise",Candidatos!F8,"") | G8: =IF(Candidatos!$K8="Em analise",Candidatos!G8,"") | H8: =IF(Candidatos!$K8="Em analise",Candidatos!H8,"") | ... K8: =IF(Candidatos!$K8="Em analise",Candidatos!K8,"") | L8: =IF(Candidatos!$K8="Em analise",Candidatos!M8,"")
A9: =IF(Candidatos!$K9="Em analise",Candidatos!A9,"") | B9: =IF(Candidatos!$K9="Em analise",Candidatos!B9,"") | C9: =IF(Candidatos!$K9="Em analise",Candidatos!C9,"") | D9: =IF(Candidatos!$K9="Em analise",Candidatos!D9,"") | E9: =IF(Candidatos!$K9="Em analise",Candidatos!E9,"") | F9: =IF(Candidatos!$K9="Em analise",Candidatos!F9,"") | G9: =IF(Candidatos!$K9="Em analise",Candidatos!G9,"") | H9: =IF(Candidatos!$K9="Em analise",Candidatos!H9,"") | ... K9: =IF(Candidatos!$K9="Em analise",Candidatos!K9,"") | L9: =IF(Candidatos!$K9="Em analise",Candidatos!M9,"")
A10: =IF(Candidatos!$K10="Em analise",Candidatos!A10,"") | B10: =IF(Candidatos!$K10="Em analise",Candidatos!B10,"") | C10: =IF(Candidatos!$K10="Em analise",Candidatos!C10,"") | D10: =IF(Candidatos!$K10="Em analise",Candidatos!D10,"") | E10: =IF(Candidatos!$K10="Em analise",Candidatos!E10,"") | F10: =IF(Candidatos!$K10="Em analise",Candidatos!F10,"") | G10: =IF(Candidatos!$K10="Em analise",Candidatos!G10,"") | H10: =IF(Candidatos!$K10="Em analise",Candidatos!H10,"") | ... K10: =IF(Candidatos!$K10="Em analise",Candidatos!K10,"") | L10: =IF(Candidatos!$K10="Em analise",Candidatos!M10,"")
A11: =IF(Candidatos!$K11="Em analise",Candidatos!A11,"") | B11: =IF(Candidatos!$K11="Em analise",Candidatos!B11,"") | C11: =IF(Candidatos!$K11="Em analise",Candidatos!C11,"") | D11: =IF(Candidatos!$K11="Em analise",Candidatos!D11,"") | E11: =IF(Candidatos!$K11="Em analise",Candidatos!E11,"") | F11: =IF(Candidatos!$K11="Em analise",Candidatos!F11,"") | G11: =IF(Candidatos!$K11="Em analise",Candidatos!G11,"") | H11: =IF(Candidatos!$K11="Em analise",Candidatos!H11,"") | ... K11: =IF(Candidatos!$K11="Em analise",Candidatos!K11,"") | L11: =IF(Candidatos!$K11="Em analise",Candidatos!M11,"")
A12: =IF(Candidatos!$K12="Em analise",Candidatos!A12,"") | B12: =IF(Candidatos!$K12="Em analise",Candidatos!B12,"") | C12: =IF(Candidatos!$K12="Em analise",Candidatos!C12,"") | D12: =IF(Candidatos!$K12="Em analise",Candidatos!D12,"") | E12: =IF(Candidatos!$K12="Em analise",Candidatos!E12,"") | F12: =IF(Candidatos!$K12="Em analise",Candidatos!F12,"") | G12: =IF(Candidatos!$K12="Em analise",Candidatos!G12,"") | H12: =IF(Candidatos!$K12="Em analise",Candidatos!H12,"") | ... K12: =IF(Candidatos!$K12="Em analise",Candidatos!K12,"") | L12: =IF(Candidatos!$K12="Em analise",Candidatos!M12,"")
A13: =IF(Candidatos!$K13="Em analise",Candidatos!A13,"") | B13: =IF(Candidatos!$K13="Em analise",Candidatos!B13,"") | C13: =IF(Candidatos!$K13="Em analise",Candidatos!C13,"") | D13: =IF(Candidatos!$K13="Em analise",Candidatos!D13,"") | E13: =IF(Candidatos!$K13="Em analise",Candidatos!E13,"") | F13: =IF(Candidatos!$K13="Em analise",Candidatos!F13,"") | G13: =IF(Candidatos!$K13="Em analise",Candidatos!G13,"") | H13: =IF(Candidatos!$K13="Em analise",Candidatos!H13,"") | ... K13: =IF(Candidatos!$K13="Em analise",Candidatos!K13,"") | L13: =IF(Candidatos!$K13="Em analise",Candidatos!M13,"")
... A281: =IF(Candidatos!$K281="Em analise",Candidatos!A281,"") | B281: =IF(Candidatos!$K281="Em analise",Candidatos!B281,"") | C281: =IF(Candidatos!$K281="Em analise",Candidatos!C281,"") | D281: =IF(Candidatos!$K281="Em analise",Candidatos!D281,"") | E281: =IF(Candidatos!$K281="Em analise",Candidatos!E281,"") | F281: =IF(Candidatos!$K281="Em analise",Candidatos!F281,"") | G281: =IF(Candidatos!$K281="Em analise",Candidatos!G281,"") | H281: =IF(Candidatos!$K281="Em analise",Candidatos!H281,"") | ... K281: =IF(Candidatos!$K281="Em analise",Candidatos!K281,"") | L281: =IF(Candidatos!$K281="Em analise",Candidatos!M281,"")
A282: =IF(Candidatos!$K282="Em analise",Candidatos!A282,"") | B282: =IF(Candidatos!$K282="Em analise",Candidatos!B282,"") | C282: =IF(Candidatos!$K282="Em analise",Candidatos!C282,"") | D282: =IF(Candidatos!$K282="Em analise",Candidatos!D282,"") | E282: =IF(Candidatos!$K282="Em analise",Candidatos!E282,"") | F282: =IF(Candidatos!$K282="Em analise",Candidatos!F282,"") | G282: =IF(Candidatos!$K282="Em analise",Candidatos!G282,"") | H282: =IF(Candidatos!$K282="Em analise",Candidatos!H282,"") | I282: =IF(Candidatos!$K282="Em analise",Candidatos!I283,"") | J282: =IF(Candidatos!$K282="Em analise",Candidatos!J282,"") | K282: =IF(Candidatos!$K282="Em analise",Candidatos!K282,"") | L282: =IF(Candidatos!$K282="Em analise",Candidatos!M282,"")
A283: =IF(Candidatos!$K283="Em analise",Candidatos!A283,"") | B283: =IF(Candidatos!$K283="Em analise",Candidatos!B283,"") | C283: =IF(Candidatos!$K283="Em analise",Candidatos!C283,"") | D283: =IF(Candidatos!$K283="Em analise",Candidatos!D283,"") | E283: =IF(Candidatos!$K283="Em analise",Candidatos!E283,"") | F283: =IF(Candidatos!$K283="Em analise",Candidatos!F283,"") | G283: =IF(Candidatos!$K283="Em analise",Candidatos!G283,"") | H283: =IF(Candidatos!$K283="Em analise",Candidatos!H283,"") | I283: =IF(Candidatos!$K283="Em analise",#REF!,"") | J283: =IF(Candidatos!$K283="Em analise",Candidatos!J283,"") | K283: =IF(Candidatos!$K283="Em analise",Candidatos!K283,"") | L283: =IF(Candidatos!$K283="Em analise",Candidatos!M283,"")
A284: =IF(Candidatos!$K284="Em analise",Candidatos!A284,"") | B284: =IF(Candidatos!$K284="Em analise",Candidatos!B284,"") | C284: =IF(Candidatos!$K284="Em analise",Candidatos!C284,"") | D284: =IF(Candidatos!$K284="Em analise",Candidatos!D284,"") | E284: =IF(Candidatos!$K284="Em analise",Candidatos!E284,"") | F284: =IF(Candidatos!$K284="Em analise",Candidatos!F284,"") | G284: =IF(Candidatos!$K284="Em analise",Candidatos!G284,"") | H284: =IF(Candidatos!$K284="Em analise",Candidatos!H284,"") | ... K284: =IF(Candidatos!$K284="Em analise",Candidatos!K284,"") | L284: =IF(Candidatos!$K284="Em analise",Candidatos!M284,"")
A285: =IF(Candidatos!$K285="Em analise",Candidatos!A285,"") | B285: =IF(Candidatos!$K285="Em analise",Candidatos!B285,"") | C285: =IF(Candidatos!$K285="Em analise",Candidatos!C285,"") | D285: =IF(Candidatos!$K285="Em analise",Candidatos!D285,"") | E285: =IF(Candidatos!$K285="Em analise",Candidatos!E285,"") | F285: =IF(Candidatos!$K285="Em analise",Candidatos!F285,"") | G285: =IF(Candidatos!$K285="Em analise",Candidatos!G285,"") | H285: =IF(Candidatos!$K285="Em analise",Candidatos!H285,"") | ... K285: =IF(Candidatos!$K285="Em analise",Candidatos!K285,"") | L285: =IF(Candidatos!$K285="Em analise",Candidatos!M285,"")
A286: =IF(Candidatos!$K286="Em analise",Candidatos!A286,"") | B286: =IF(Candidatos!$K286="Em analise",Candidatos!B286,"") | C286: =IF(Candidatos!$K286="Em analise",Candidatos!C286,"") | D286: =IF(Candidatos!$K286="Em analise",Candidatos!D286,"") | E286: =IF(Candidatos!$K286="Em analise",Candidatos!E286,"") | F286: =IF(Candidatos!$K286="Em analise",Candidatos!F286,"") | G286: =IF(Candidatos!$K286="Em analise",Candidatos!G286,"") | H286: =IF(Candidatos!$K286="Em analise",Candidatos!H286,"") | ... K286: =IF(Candidatos!$K286="Em analise",Candidatos!K286,"") | L286: =IF(Candidatos!$K286="Em analise",Candidatos!M286,"")
A287: =IF(Candidatos!$K287="Em analise",Candidatos!A287,"") | B287: =IF(Candidatos!$K287="Em analise",Candidatos!B287,"") | C287: =IF(Candidatos!$K287="Em analise",Candidatos!C287,"") | D287: =IF(Candidatos!$K287="Em analise",Candidatos!D287,"") | E287: =IF(Candidatos!$K287="Em analise",Candidatos!E287,"") | F287: =IF(Candidatos!$K287="Em analise",Candidatos!F287,"") | G287: =IF(Candidatos!$K287="Em analise",Candidatos!G287,"") | H287: =IF(Candidatos!$K287="Em analise",Candidatos!H287,"") | ... K287: =IF(Candidatos!$K287="Em analise",Candidatos!K287,"") | L287: =IF(Candidatos!$K287="Em analise",Candidatos!M287,"")
A288: =IF(Candidatos!$K288="Em analise",Candidatos!A288,"") | B288: =IF(Candidatos!$K288="Em analise",Candidatos!B288,"") | C288: =IF(Candidatos!$K288="Em analise",Candidatos!C288,"") | D288: =IF(Candidatos!$K288="Em analise",Candidatos!D288,"") | E288: =IF(Candidatos!$K288="Em analise",Candidatos!E288,"") | F288: =IF(Candidatos!$K288="Em analise",Candidatos!F288,"") | G288: =IF(Candidatos!$K288="Em analise",Candidatos!G288,"") | H288: =IF(Candidatos!$K288="Em analise",Candidatos!H288,"") | ... K288: =IF(Candidatos!$K288="Em analise",Candidatos!K288,"") | L288: =IF(Candidatos!$K288="Em analise",Candidatos!M288,"")
A289: =IF(Candidatos!$K289="Em analise",Candidatos!A289,"") | B289: =IF(Candidatos!$K289="Em analise",Candidatos!B289,"") | C289: =IF(Candidatos!$K289="Em analise",Candidatos!C289,"") | D289: =IF(Candidatos!$K289="Em analise",Candidatos!D289,"") | E289: =IF(Candidatos!$K289="Em analise",Candidatos!E289,"") | F289: =IF(Candidatos!$K289="Em analise",Candidatos!F289,"") | G289: =IF(Candidatos!$K289="Em analise",Candidatos!G289,"") | H289: =IF(Candidatos!$K289="Em analise",Candidatos!H289,"") | ... K289: =IF(Candidatos!$K289="Em analise",Candidatos!K289,"") | L289: =IF(Candidatos!$K289="Em analise",Candidatos!M289,"")
A290: =IF(Candidatos!$K290="Em analise",Candidatos!A290,"") | B290: =IF(Candidatos!$K290="Em analise",Candidatos!B290,"") | C290: =IF(Candidatos!$K290="Em analise",Candidatos!C290,"") | D290: =IF(Candidatos!$K290="Em analise",Candidatos!D290,"") | E290: =IF(Candidatos!$K290="Em analise",Candidatos!E290,"") | F290: =IF(Candidatos!$K290="Em analise",Candidatos!F290,"") | G290: =IF(Candidatos!$K290="Em analise",Candidatos!G290,"") | H290: =IF(Candidatos!$K290="Em analise",Candidatos!H290,"") | ... K290: =IF(Candidatos!$K290="Em analise",Candidatos!K290,"") | L290: =IF(Candidatos!$K290="Em analise",Candidatos!M290,"")
A291: =IF(Candidatos!$K291="Em analise",Candidatos!A291,"") | B291: =IF(Candidatos!$K291="Em analise",Candidatos!B291,"") | C291: =IF(Candidatos!$K291="Em analise",Candidatos!C291,"") | D291: =IF(Candidatos!$K291="Em analise",Candidatos!D291,"") | E291: =IF(Candidatos!$K291="Em analise",Candidatos!E291,"") | F291: =IF(Candidatos!$K291="Em analise",Candidatos!F291,"") | G291: =IF(Candidatos!$K291="Em analise",Candidatos!G291,"") | H291: =IF(Candidatos!$K291="Em analise",Candidatos!H291,"") | ... K291: =IF(Candidatos!$K291="Em analise",Candidatos!K291,"") | L291: =IF(Candidatos!$K291="Em analise",Candidatos!M291,"")
A292: =IF(Candidatos!$K292="Em analise",Candidatos!A292,"") | B292: =IF(Candidatos!$K292="Em analise",Candidatos!B292,"") | C292: =IF(Candidatos!$K292="Em analise",Candidatos!C292,"") | D292: =IF(Candidatos!$K292="Em analise",Candidatos!D292,"") | E292: =IF(Candidatos!$K292="Em analise",Candidatos!E292,"") | F292: =IF(Candidatos!$K292="Em analise",Candidatos!F292,"") | G292: =IF(Candidatos!$K292="Em analise",Candidatos!G292,"") | H292: =IF(Candidatos!$K292="Em analise",Candidatos!H292,"") | ... K292: =IF(Candidatos!$K292="Em analise",Candidatos!K292,"") | L292: =IF(Candidatos!$K292="Em analise",Candidatos!M292,"")
A293: =IF(Candidatos!$K293="Em analise",Candidatos!A293,"") | B293: =IF(Candidatos!$K293="Em analise",Candidatos!B293,"") | C293: =IF(Candidatos!$K293="Em analise",Candidatos!C293,"") | D293: =IF(Candidatos!$K293="Em analise",Candidatos!D293,"") | E293: =IF(Candidatos!$K293="Em analise",Candidatos!E293,"") | F293: =IF(Candidatos!$K293="Em analise",Candidatos!F293,"") | G293: =IF(Candidatos!$K293="Em analise",Candidatos!G293,"") | H293: =IF(Candidatos!$K293="Em analise",Candidatos!H293,"") | ... K293: =IF(Candidatos!$K293="Em analise",Candidatos!K293,"") | L293: =IF(Candidatos!$K293="Em analise",Candidatos!M293,"")
A294: =IF(Candidatos!$K294="Em analise",Candidatos!A294,"") | B294: =IF(Candidatos!$K294="Em analise",Candidatos!B294,"") | C294: =IF(Candidatos!$K294="Em analise",Candidatos!C294,"") | D294: =IF(Candidatos!$K294="Em analise",Candidatos!D294,"") | E294: =IF(Candidatos!$K294="Em analise",Candidatos!E294,"") | F294: =IF(Candidatos!$K294="Em analise",Candidatos!F294,"") | G294: =IF(Candidatos!$K294="Em analise",Candidatos!G294,"") | H294: =IF(Candidatos!$K294="Em analise",Candidatos!H294,"") | ... K294: =IF(Candidatos!$K294="Em analise",Candidatos!K294,"") | L294: =IF(Candidatos!$K294="Em analise",Candidatos!M294,"")
A295: =IF(Candidatos!$K295="Em analise",Candidatos!A295,"") | B295: =IF(Candidatos!$K295="Em analise",Candidatos!B295,"") | C295: =IF(Candidatos!$K295="Em analise",Candidatos!C295,"") | D295: =IF(Candidatos!$K295="Em analise",Candidatos!D295,"") | E295: =IF(Candidatos!$K295="Em analise",Candidatos!E295,"") | F295: =IF(Candidatos!$K295="Em analise",Candidatos!F295,"") | G295: =IF(Candidatos!$K295="Em analise",Candidatos!G295,"") | H295: =IF(Candidatos!$K295="Em analise",Candidatos!H295,"") | ... K295: =IF(Candidatos!$K295="Em analise",Candidatos!K295,"") | L295: =IF(Candidatos!$K295="Em analise",Candidatos!M295,"")
... A360: =IF(Candidatos!$K360="Em analise",Candidatos!A360,"") | B360: =IF(Candidatos!$K360="Em analise",Candidatos!B360,"") | C360: =IF(Candidatos!$K360="Em analise",Candidatos!C360,"") | D360: =IF(Candidatos!$K360="Em analise",Candidatos!D360,"") | E360: =IF(Candidatos!$K360="Em analise",Candidatos!E360,"") | F360: =IF(Candidatos!$K360="Em analise",Candidatos!F360,"") | G360: =IF(Candidatos!$K360="Em analise",Candidatos!G360,"") | H360: =IF(Candidatos!$K360="Em analise",Candidatos!H360,"") | ... K360: =IF(Candidatos!$K360="Em analise",Candidatos!K360,"") | L360: =IF(Candidatos!$K360="Em analise",Candidatos!M360,"")
A361: =IF(Candidatos!$K361="Em analise",Candidatos!A361,"") | B361: =IF(Candidatos!$K361="Em analise",Candidatos!B361,"") | C361: =IF(Candidatos!$K361="Em analise",Candidatos!C361,"") | D361: =IF(Candidatos!$K361="Em analise",Candidatos!D361,"") | E361: =IF(Candidatos!$K361="Em analise",Candidatos!E361,"") | F361: =IF(Candidatos!$K361="Em analise",Candidatos!F361,"") | G361: =IF(Candidatos!$K361="Em analise",Candidatos!G361,"") | H361: =IF(Candidatos!$K361="Em analise",Candidatos!H361,"") | I361: =IF(Candidatos!$K361="Em analise",#REF!,"") | J361: =IF(Candidatos!$K361="Em analise",Candidatos!J361,"") | K361: =IF(Candidatos!$K361="Em analise",Candidatos!K361,"") | L361: =IF(Candidatos!$K361="Em analise",Candidatos!M361,"")
A362: =IF(Candidatos!$K362="Em analise",Candidatos!A362,"") | B362: =IF(Candidatos!$K362="Em analise",Candidatos!B362,"") | C362: =IF(Candidatos!$K362="Em analise",Candidatos!C362,"") | D362: =IF(Candidatos!$K362="Em analise",Candidatos!D362,"") | E362: =IF(Candidatos!$K362="Em analise",Candidatos!E362,"") | F362: =IF(Candidatos!$K362="Em analise",Candidatos!F362,"") | G362: =IF(Candidatos!$K362="Em analise",Candidatos!G362,"") | H362: =IF(Candidatos!$K362="Em analise",Candidatos!H362,"") | I362: =IF(Candidatos!$K362="Em analise",Candidatos!I361,"") | J362: =IF(Candidatos!$K362="Em analise",Candidatos!J362,"") | K362: =IF(Candidatos!$K362="Em analise",Candidatos!K362,"") | L362: =IF(Candidatos!$K362="Em analise",Candidatos!M362,"")
A363: =IF(Candidatos!$K363="Em analise",Candidatos!A363,"") | B363: =IF(Candidatos!$K363="Em analise",Candidatos!B363,"") | C363: =IF(Candidatos!$K363="Em analise",Candidatos!C363,"") | D363: =IF(Candidatos!$K363="Em analise",Candidatos!D363,"") | E363: =IF(Candidatos!$K363="Em analise",Candidatos!E363,"") | F363: =IF(Candidatos!$K363="Em analise",Candidatos!F363,"") | G363: =IF(Candidatos!$K363="Em analise",Candidatos!G363,"") | H363: =IF(Candidatos!$K363="Em analise",Candidatos!H363,"") | ... K363: =IF(Candidatos!$K363="Em analise",Candidatos!K363,"") | L363: =IF(Candidatos!$K363="Em analise",Candidatos!M363,"")
A364: =IF(Candidatos!$K364="Em analise",Candidatos!A364,"") | B364: =IF(Candidatos!$K364="Em analise",Candidatos!B364,"") | C364: =IF(Candidatos!$K364="Em analise",Candidatos!C364,"") | D364: =IF(Candidatos!$K364="Em analise",Candidatos!D364,"") | E364: =IF(Candidatos!$K364="Em analise",Candidatos!E364,"") | F364: =IF(Candidatos!$K364="Em analise",Candidatos!F364,"") | G364: =IF(Candidatos!$K364="Em analise",Candidatos!G364,"") | H364: =IF(Candidatos!$K364="Em analise",Candidatos!H364,"") | ... K364: =IF(Candidatos!$K364="Em analise",Candidatos!K364,"") | L364: =IF(Candidatos!$K364="Em analise",Candidatos!M364,"")
A365: =IF(Candidatos!$K365="Em analise",Candidatos!A365,"") | B365: =IF(Candidatos!$K365="Em analise",Candidatos!B365,"") | C365: =IF(Candidatos!$K365="Em analise",Candidatos!C365,"") | D365: =IF(Candidatos!$K365="Em analise",Candidatos!D365,"") | E365: =IF(Candidatos!$K365="Em analise",Candidatos!E365,"") | F365: =IF(Candidatos!$K365="Em analise",Candidatos!F365,"") | G365: =IF(Candidatos!$K365="Em analise",Candidatos!G365,"") | H365: =IF(Candidatos!$K365="Em analise",Candidatos!H365,"") | ... K365: =IF(Candidatos!$K365="Em analise",Candidatos!K365,"") | L365: =IF(Candidatos!$K365="Em analise",Candidatos!M365,"")
A366: =IF(Candidatos!$K366="Em analise",Candidatos!A366,"") | B366: =IF(Candidatos!$K366="Em analise",Candidatos!B366,"") | C366: =IF(Candidatos!$K366="Em analise",Candidatos!C366,"") | D366: =IF(Candidatos!$K366="Em analise",Candidatos!D366,"") | E366: =IF(Candidatos!$K366="Em analise",Candidatos!E366,"") | F366: =IF(Candidatos!$K366="Em analise",Candidatos!F366,"") | G366: =IF(Candidatos!$K366="Em analise",Candidatos!G366,"") | H366: =IF(Candidatos!$K366="Em analise",Candidatos!H366,"") | ... K366: =IF(Candidatos!$K366="Em analise",Candidatos!K366,"") | L366: =IF(Candidatos!$K366="Em analise",Candidatos!M366,"")
A367: =IF(Candidatos!$K367="Em analise",Candidatos!A367,"") | B367: =IF(Candidatos!$K367="Em analise",Candidatos!B367,"") | C367: =IF(Candidatos!$K367="Em analise",Candidatos!C367,"") | D367: =IF(Candidatos!$K367="Em analise",Candidatos!D367,"") | E367: =IF(Candidatos!$K367="Em analise",Candidatos!E367,"") | F367: =IF(Candidatos!$K367="Em analise",Candidatos!F367,"") | G367: =IF(Candidatos!$K367="Em analise",Candidatos!G367,"") | H367: =IF(Candidatos!$K367="Em analise",Candidatos!H367,"") | ... K367: =IF(Candidatos!$K367="Em analise",Candidatos!K367,"") | L367: =IF(Candidatos!$K367="Em analise",Candidatos!M367,"")
A368: =IF(Candidatos!$K368="Em analise",Candidatos!A368,"") | B368: =IF(Candidatos!$K368="Em analise",Candidatos!B368,"") | C368: =IF(Candidatos!$K368="Em analise",Candidatos!C368,"") | D368: =IF(Candidatos!$K368="Em analise",Candidatos!D368,"") | E368: =IF(Candidatos!$K368="Em analise",Candidatos!E368,"") | F368: =IF(Candidatos!$K368="Em analise",Candidatos!F368,"") | G368: =IF(Candidatos!$K368="Em analise",Candidatos!G368,"") | H368: =IF(Candidatos!$K368="Em analise",Candidatos!H368,"") | ... K368: =IF(Candidatos!$K368="Em analise",Candidatos!K368,"") | L368: =IF(Candidatos!$K368="Em analise",Candidatos!M368,"")
A369: =IF(Candidatos!$K369="Em analise",Candidatos!A369,"") | B369: =IF(Candidatos!$K369="Em analise",Candidatos!B369,"") | C369: =IF(Candidatos!$K369="Em analise",Candidatos!C369,"") | D369: =IF(Candidatos!$K369="Em analise",Candidatos!D369,"") | E369: =IF(Candidatos!$K369="Em analise",Candidatos!E369,"") | F369: =IF(Candidatos!$K369="Em analise",Candidatos!F369,"") | G369: =IF(Candidatos!$K369="Em analise",Candidatos!G369,"") | H369: =IF(Candidatos!$K369="Em analise",Candidatos!H369,"") | ... K369: =IF(Candidatos!$K369="Em analise",Candidatos!K369,"") | L369: =IF(Candidatos!$K369="Em analise",Candidatos!M369,"")
A370: =IF(Candidatos!$K370="Em analise",Candidatos!A370,"") | B370: =IF(Candidatos!$K370="Em analise",Candidatos!B370,"") | C370: =IF(Candidatos!$K370="Em analise",Candidatos!C370,"") | D370: =IF(Candidatos!$K370="Em analise",Candidatos!D370,"") | E370: =IF(Candidatos!$K370="Em analise",Candidatos!E370,"") | F370: =IF(Candidatos!$K370="Em analise",Candidatos!F370,"") | G370: =IF(Candidatos!$K370="Em analise",Candidatos!G370,"") | H370: =IF(Candidatos!$K370="Em analise",Candidatos!H370,"") | ... K370: =IF(Candidatos!$K370="Em analise",Candidatos!K370,"") | L370: =IF(Candidatos!$K370="Em analise",Candidatos!M370,"")
A371: =IF(Candidatos!$K371="Em analise",Candidatos!A371,"") | B371: =IF(Candidatos!$K371="Em analise",Candidatos!B371,"") | C371: =IF(Candidatos!$K371="Em analise",Candidatos!C371,"") | D371: =IF(Candidatos!$K371="Em analise",Candidatos!D371,"") | E371: =IF(Candidatos!$K371="Em analise",Candidatos!E371,"") | F371: =IF(Candidatos!$K371="Em analise",Candidatos!F371,"") | G371: =IF(Candidatos!$K371="Em analise",Candidatos!G371,"") | H371: =IF(Candidatos!$K371="Em analise",Candidatos!H371,"") | ... K371: =IF(Candidatos!$K371="Em analise",Candidatos!K371,"") | L371: =IF(Candidatos!$K371="Em analise",Candidatos!M371,"")
...

Sheet Negado
A1: Nome do inscrito(a) | B1: Data de inscrição | C1: e-mail | D1: Contato | E1: Região | F1: Turma | G1: Idade | H1: Renda Familiar | I1: Equipe NAU | J1: Agendamento | K1: Motivo | L1: Comentarios
A2: =IF(Candidatos!$K2="Negado",Candidatos!A2,"") | B2: =IF(Candidatos!$K2="Negado",Candidatos!B2,"") | C2: =IF(Candidatos!$K2="Negado",Candidatos!C2,"") | D2: =IF(Candidatos!$K2="Negado",Candidatos!D2,"") | E2: =IF(Candidatos!$K2="Negado",Candidatos!E2,"") | F2: =IF(Candidatos!$K2="Negado",Candidatos!F2,"") | G2: =IF(Candidatos!$K2="Negado",Candidatos!G2,"") | H2: =IF(Candidatos!$K2="Negado",Candidatos!H2,"") | ... J2: =IF(Candidatos!$K2="Negado",Candidatos!J2,"") | K2: =IF(Candidatos!$K2="Negado",Candidatos!L2,"") | L2: =IF(Candidatos!$K2="Negado",Candidatos!M2,"")
A3: =IF(Candidatos!$K3="Negado",Candidatos!A3,"") | B3: =IF(Candidatos!$K3="Negado",Candidatos!B3,"") | C3: =IF(Candidatos!$K3="Negado",Candidatos!C3,"") | D3: =IF(Candidatos!$K3="Negado",Candidatos!D3,"") | E3: =IF(Candidatos!$K3="Negado",Candidatos!E3,"") | F3: =IF(Candidatos!$K3="Negado",Candidatos!F3,"") | G3: =IF(Candidatos!$K3="Negado",Candidatos!G3,"") | H3: =IF(Candidatos!$K3="Negado",Candidatos!H3,"") | ... J3: =IF(Candidatos!$K3="Negado",Candidatos!J3,"") | K3: =IF(Candidatos!$K3="Negado",Candidatos!L3,"") | L3: =IF(Candidatos!$K3="Negado",Candidatos!M3,"")
A4: =IF(Candidatos!$K4="Negado",Candidatos!A4,"") | B4: =IF(Candidatos!$K4="Negado",Candidatos!B4,"") | C4: =IF(Candidatos!$K4="Negado",Candidatos!C4,"") | D4: =IF(Candidatos!$K4="Negado",Candidatos!D4,"") | E4: =IF(Candidatos!$K4="Negado",Candidatos!E4,"") | F4: =IF(Candidatos!$K4="Negado",Candidatos!F4,"") | G4: =IF(Candidatos!$K4="Negado",Candidatos!G4,"") | H4: =IF(Candidatos!$K4="Negado",Candidatos!H4,"") | ... J4: =IF(Candidatos!$K4="Negado",Candidatos!J4,"") | K4: =IF(Candidatos!$K4="Negado",Candidatos!L4,"") | L4: =IF(Candidatos!$K4="Negado",Candidatos!M4,"")
